2024-08-13 15:00:21,975 ERROR Error fetching movie data: Traceback (most recent call last):
  File "/var/src/web/afh/job/afh_kkphim_url.py", line 61, in update_kk_phim
    movieData = requests.get(detailUrl).json()
  File "/usr/local/lib/python3.8/dist-packages/requests/models.py", line 910, in json
    return complexjson.loads(self.text, **kwargs)
  File "/usr/lib/python3/dist-packages/simplejson/__init__.py", line 518, in loads
    return _default_decoder.decode(s)
  File "/usr/lib/python3/dist-packages/simplejson/decoder.py", line 373, in decode
    raise JSONDecodeError("Extra data", s, end, len(s))
simplejson.errors.JSONDecodeError: Extra data: line 1 column 31 - line 1 column 107 (char 30 - 106)

2024-08-14 02:42:09,609 ERROR Error fetching movie data: Traceback (most recent call last):
  File "/usr/local/lib/python3.8/dist-packages/urllib3/connection.py", line 169, in _new_conn
    conn = connection.create_connection(
  File "/usr/local/lib/python3.8/dist-packages/urllib3/util/connection.py", line 96, in create_connection
    raise err
  File "/usr/local/lib/python3.8/dist-packages/urllib3/util/connection.py", line 86, in create_connection
    sock.connect(sa)
TimeoutError: [Errno 110] Connection timed out

During handling of the above exception, another exception occurred:

Traceback (most recent call last):
  File "/usr/local/lib/python3.8/dist-packages/urllib3/connectionpool.py", line 699, in urlopen
    httplib_response = self._make_request(
  File "/usr/local/lib/python3.8/dist-packages/urllib3/connectionpool.py", line 382, in _make_request
    self._validate_conn(conn)
  File "/usr/local/lib/python3.8/dist-packages/urllib3/connectionpool.py", line 1010, in _validate_conn
    conn.connect()
  File "/usr/local/lib/python3.8/dist-packages/urllib3/connection.py", line 353, in connect
    conn = self._new_conn()
  File "/usr/local/lib/python3.8/dist-packages/urllib3/connection.py", line 181, in _new_conn
    raise NewConnectionError(
urllib3.exceptions.NewConnectionError: <urllib3.connection.HTTPSConnection object at 0x7f59966eebb0>: Failed to establish a new connection: [Errno 110] Connection timed out

During handling of the above exception, another exception occurred:

Traceback (most recent call last):
  File "/usr/local/lib/python3.8/dist-packages/requests/adapters.py", line 439, in send
    resp = conn.urlopen(
  File "/usr/local/lib/python3.8/dist-packages/urllib3/connectionpool.py", line 755, in urlopen
    retries = retries.increment(
  File "/usr/local/lib/python3.8/dist-packages/urllib3/util/retry.py", line 574, in increment
    raise MaxRetryError(_pool, url, error or ResponseError(cause))
urllib3.exceptions.MaxRetryError: HTTPSConnectionPool(host='phimapi.com', port=443): Max retries exceeded with url: /phim/linh-vu-dai-luc (Caused by NewConnectionError('<urllib3.connection.HTTPSConnection object at 0x7f59966eebb0>: Failed to establish a new connection: [Errno 110] Connection timed out'))

During handling of the above exception, another exception occurred:

Traceback (most recent call last):
  File "/var/src/web/afh/job/afh_kkphim_url.py", line 61, in update_kk_phim
    movieData = requests.get(detailUrl).json()
  File "/usr/local/lib/python3.8/dist-packages/requests/api.py", line 75, in get
    return request('get', url, params=params, **kwargs)
  File "/usr/local/lib/python3.8/dist-packages/requests/api.py", line 61, in request
    return session.request(method=method, url=url, **kwargs)
  File "/usr/local/lib/python3.8/dist-packages/requests/sessions.py", line 542, in request
    resp = self.send(prep, **send_kwargs)
  File "/usr/local/lib/python3.8/dist-packages/requests/sessions.py", line 655, in send
    r = adapter.send(request, **kwargs)
  File "/usr/local/lib/python3.8/dist-packages/requests/adapters.py", line 516, in send
    raise ConnectionError(e, request=request)
requests.exceptions.ConnectionError: HTTPSConnectionPool(host='phimapi.com', port=443): Max retries exceeded with url: /phim/linh-vu-dai-luc (Caused by NewConnectionError('<urllib3.connection.HTTPSConnection object at 0x7f59966eebb0>: Failed to establish a new connection: [Errno 110] Connection timed out'))

